Workbook

Sheet Portada
B2: ECOS DEL GRIMORIO
B3: Libro de producción · Proceso Huddle · Sprints 1 a 4
B5: Alumno | C5: Alejandro Pérez Alcántara
B6: Grupo | C6: 10° "D"
B7: Materia | C7: Creación de Videojuegos
B8: Docente | C8: José Francisco Espinosa Garita
B9: Universidad | C9: Universidad Tecnológica de Puebla
B10: Motor | C10: Unity 6 (6000.6.0f1), 2D URP, C#
B11: Jugar en línea | C11: https://alexap1115web.github.io/Ecos-Del-Grimorio/
B12: Repositorio | C12: https://github.com/AlexAP1115web/Ecos-Del-Grimorio
B13: Versión del documento | C13: 1.0
B14: Última actualización | C14: 46318
B16: Resumen por sprint
B17: Sprint | C17: Inicio | D17: Fin | E17: Estado | F17: Tareas | G17: Terminadas | H17: Avance (horas)
B18: Sprint 1 | C18: ='Sprint Plan'!B4 -> 46266 | D18: ='Sprint Plan'!D4 -> 46283 | E18: ='Sprint Plan'!E4 -> Terminado | F18: ='Sprint Backlog'!E88 -> 10 | G18: ='Sprint Backlog'!F88 -> 10 | H18: ='Sprint Backlog'!I88 -> 1
B19: Sprint 2 | C19: ='Sprint Plan'!B5 -> 46284 | D19: ='Sprint Plan'!D5 -> 46325 | E19: ='Sprint Plan'!E5 -> En desarrollo | F19: ='Sprint Backlog'!E89 -> 53 | G19: ='Sprint Backlog'!F89 -> 48 | H19: ='Sprint Backlog'!I89 -> 0.94202899
B20: Sprint 3 | C20: ='Sprint Plan'!B6 -> 46326 | D20: ='Sprint Plan'!D6 -> 46346 | E20: ='Sprint Plan'!E6 -> Planeado | F20: ='Sprint Backlog'!E90 -> 12 | G20: ='Sprint Backlog'!F90 -> 2 | H20: ='Sprint Backlog'!I90 -> 0.11111111
B21: Sprint 4 | C21: ='Sprint Plan'!B7 -> 46347 | D21: ='Sprint Plan'!D7 -> 46356 | E21: ='Sprint Plan'!E7 -> Planeado | F21: ='Sprint Backlog'!E91 -> 7 | G21: ='Sprint Backlog'!F91 -> 0 | H21: ='Sprint Backlog'!I91 -> 0
B22: Total | F22: ='Sprint Backlog'!E92 -> 82 | G22: ='Sprint Backlog'!F92 -> 60 | H22: ='Sprint Backlog'!I92 -> 0.82638889
B24: Contenido del libro
B25: Hoja | C25: Contenido
B26: Feature Log | C26: Registro de features, estado y sprint asignado.
B27: Sprint Plan | C27: Calendario, objetivo y entregable por sprint.
B28: Sprint Backlog | C28: Tareas por sprint con feature, estado, esfuerzo y fechas; resumen de avance.
B29: Daily Huddle | C29: Registro de avance, plan e impedimentos por sesión.
B30: Project Chart | C30: Distribución de features por estado.
B31: Burn-down Chart | C31: Trabajo restante real contra ideal, por sprint.
B32: Task Chart | C32: Tareas terminadas y restantes por fecha de corte, por sprint.
B33: Buglist | C33: Registro de defectos, severidad y estado de corrección.
B34: Pruebas Alfa | C34: Casos de prueba internos y resultados.
B35: Evaluación Beta | C35: Matriz de cumplimiento de la rúbrica y pruebas de compatibilidad.
B36: Matriz GDD | C36: Trazabilidad entre GDD, features y tareas.
... B38: Sprint Review | C38: Indicadores y retrospectiva por sprint.

Sheet Feature Log
A1: FEATURE LOG - ECOS DEL GRIMORIO (todos los sprints)
A2: Nota: los features 1–14 provienen del Feature Log base (GDD 3.1); 15–26 se incorporaron en el Sprint 2 para cubrir secciones del GDD; el 27 deriva de pruebas internas; el 28, de la solicitud del docente (versión móvil); el 29 corresponde al arte de Preproducción.
A3: Featureid | B3: Nombre | C3: Estado | D3: Días | E3: Sprintid | F3: Comentarios
A4: 1 | B4: Movimiento y salto del jugador | C4: Terminado | D4: 3 | E4: 2 | F4: PlayerController.cs: aceleración, coyote time, búfer de salto, esquive, agacharse y planeo
A5: 2 | B5: Sistema de maná y hechizo Arcano | C5: Terminado | D5: 4 | E5: 2 | F5: SpellCaster.cs + SpellData.cs; tres espacios de hechizo
A6: 3 | B6: IA de patrulla/persecución básica | C6: Terminado | D6: 3 | E6: 2 | F6: EnemyBase.cs → EnemyAI, FlyingEnemyAI, RangedEnemyAI
A7: 4 | B7: Sistema de vida (jugador/enemigos) | C7: Terminado | D7: 2 | E7: 2 | F7: Health.cs + IDamageable, resistencias por elemento
A8: 5 | B8: Hechizo de Fuego y combo Explosión Arcana | C8: Terminado | D8: 5 | E8: 2 | F8: Se adelantó al Sprint 2
A9: 6 | B9: Ala de Fuego completa con jefe Kaelor (Nivel 2) | C9: Terminado | D9: 6 | E9: 2 | F9: KaelorBoss.cs, 2 fases
A10: 7 | B10: Hechizo de Hielo y combo Vapor Cegador | C10: Terminado | D10: 4 | E10: 2 | F10: Congela al tercer golpe (2.11)
A11: 8 | B11: Ala de Hielo completa con jefa Isolde (Nivel 3) | C11: Terminado | D11: 6 | E11: 2 | F11: IsoldeBoss.cs, congela el suelo
A12: 9 | B12: Hechizo de Viento y combos Granizo Cortante / Tormenta de Ascuas | C12: Terminado | D12: 5 | E12: 2 | F12: Planeado para Sprint 3, se adelantó
A13: 10 | B13: Ala de Viento completa con jefe Threnody y plataformas móviles (Nivel 4) | C13: Terminado | D13: 7 | E13: 2 | F13: Planeado para Sprint 3, se adelantó
A14: 11 | B14: Corazón del Grimorio: Ecos Menores, Guardián Espejo y jefe final multifase (Nivel 5) | C14: Terminado | D14: 8 | E14: 2 | F14: ElenoraBoss.cs, 4 fases + final. Final del juego corregido el 7 de octubre
A15: 12 | B15: Sistema de Logros (AchievementManager basado en eventos) | C15: Terminado | D15: 3 | E15: 2 | F15: 10 logros, se adelantó del Sprint 4
A16: 13 | B16: Sistema de truco / Easter egg (Modo Archimaga) | C16: Terminado | D16: 2 | E16: 2 | F16: Teclado F-H-V-A + Enter; control L1 + R1 + Triángulo
A17: 14 | B17: Integración final, pulido y Gold Master | C17: En desarrollo | D17: 5 | E17: 2-4 | F17: Pruebas Alfa en curso; Evaluación Beta en clase el 28/10; versión final en el Sprint 4
A18: 15 | B18: Menú principal, pausa, Game Over y guardado (2.4, 2.5, 2.6) | C18: Terminado | D18: 3 | E18: 2 | F18: Agregado en Sprint 2 desde el GDD
A19: 16 | B19: Pantalla de Opciones (2.5, 2.6) | C19: Terminado | D19: 1 | E19: 2 | F19: Volumen de música, efectos y voces, pantalla completa y vibración
A20: 17 | B20: HUD y pantalla de resultados por ala (2.6) | C20: Terminado | D20: 2 | E20: 2 | F20: Tiempo, enemigos, daño, páginas, secretos
A21: 18 | B21: Historia: prólogo, diálogos, epílogo y créditos (2.14) | C21: Terminado | D21: 3 | E21: 2 | F21: Prologo.cs, NPCDialogue.cs, CreditsScreen.cs
A22: 19 | B22: Música, efectos de sonido y voces (2.17) | C22: Terminado | D22: 3 | E22: 2 | F22: 9 pistas, 41 efectos (12 agregados el 15 oct) y voces por personaje
A23: 20 | B23: Control de PS4 / Xbox y vibración (2.4) | C23: Terminado | D23: 1 | E23: 2 | F23: New Input System
A24: 21 | B24: Habilidades elementales y acertijos ambientales (2.1, 2.3, 2.11) | C24: Terminado | D24: 2 | E24: 2 | F24: Zarzas, muros de hielo, cajas, placas y puertas rúnicas
A25: 22 | B25: Armas de los enemigos (2.12) | C25: Terminado | D25: 1 | E25: 2 | F25: ArmaEnemigo.cs: Garras, Lanza, Embestida
A26: 23 | B26: Ítems, coleccionables y salas secretas (2.8, 2.13) | C26: Terminado | D26: 2 | E26: 2 | F26: Páginas Perdidas, vasijas, cofres y fragmentos
A27: 24 | B27: Build del juego para Windows (.exe) (5.1) | C27: En desarrollo | D27: 1 | E27: 2-3 | F27: Menú Ecos del Grimorio > Compilar juego (.exe). Primera compilación el 13 oct y versión 1.0 el 20 oct; falta probarlo en otra computadora
A28: 25 | B28: Documentación del Producto 2 (producción y evidencias) | C28: Terminado | D28: 2 | E28: 2 | F28: Documento Word/PDF, manual del jugador y este libro de Excel
A29: 26 | B29: Pruebas Beta y reporte Postmortem | C29: En desarrollo | D29: 6 | E29: 2-4 | F29: Evaluación Beta en clase con la rúbrica del docente (28/10); Postmortem en borrador
A30: 27 | B30: Ayudas al jugador: ayuda para apuntar, sentido arcano y saltar nivel | C30: Terminado | D30: 2 | E30: 2 | F30: Agregado después de las pruebas del 14 y 15 de octubre y de la revisión en clase
A31: 28 | B31: Versión web para celular (WebGL + PWA) | C31: Terminado | D31: 1 | E31: 2 | F31: Pedido del profe en la revisión. Botones táctiles, plantilla para instalarlo como app y publicación en GitHub Pages
A32: 29 | B32: Arte conceptual: personajes, enemigos, jefes, fondos, ítems y UI (GDD) | C32: Terminado | D32: 18 | E32: 1 | F32: Preproducción. Bocetos a lápiz, arte digital y limpieza; se importó a Unity en el Sprint 2 (T01)

Sheet Sprint Plan
A1: SPRINT PLAN - ECOS DEL GRIMORIO
A2: Nota: cambios al plan base: features 9–13 adelantados al Sprint 2; la fase Beta se evalúa mediante demostración en clase con la rúbrica del docente (28/10/2026).
A3: Sprintid | B3: Inicio | C3: Días | D3: Fin | E3: Estado | F3: Meta | G3: Entrega
A4: 1 | B4: 46266 | C4: =D4-B4+1 -> 18 | D4: 46283 | E4: Terminado | F4: Preproducción y arte: GDD, bocetos, arte conceptual de personajes, enemigos, fondos, ítems y UI. | G4: Producto 1 (18 sep)
A5: 2 | B5: 46284 | C5: =D5-B5+1 -> 42 | D5: 46325 | E5: En desarrollo | F5: Juego completo jugable en Unity: 5 alas, 4 guardianes y jefe final, logros, Modo Archimaga, opciones, resultados, música y voces. Versión web para celular. Evaluación Beta en clase. | G5: Producto 2 (30 oct) y Evaluación Beta en clase (28 oct)
A6: 3 | B6: 46326 | C6: =D6-B6+1 -> 21 | D6: 46346 | E6: Planeado | F6: Registrar los resultados de la Evaluación Beta, corregir y balancear lo que salga, actualizar documentos y borrador del Postmortem. | G6: Producto 3 (20 nov)
A7: 4 | B7: 46347 | C7: =D7-B7+1 -> 10 | D7: 46356 | E7: Planeado | F7: Versión final del .exe y de la web, Postmortem completo y entrega en memoria (.exe, documento del Producto 1 y código fuente comprimido). | G7: Entrega final (30 nov)

Sheet Sprint Backlog
A1: SPRINT BACKLOG - TODOS LOS SPRINTS
A2: Nota: rangos de TaskID: Sprint 1: S1-01–S1-10; Sprint 2: T01–T53; Sprint 3: T54–T65; Sprint 4: T66–T72. La columna Fin alimenta el Burn-down y el Task Chart. S1-07 y S1-08 se cerraron en el Sprint 2 (T01).
A3: Sprint | B3: TaskID | C3: Featureid | D3: Nombre de la tarea | E3: Miembro | F3: Rol | G3: Estado | H3: Esfuerzo (hrs) | I3: Inicio | J3: Fin
A4: 1 | B4: S1-01 | C4: 29 | D4: Arte de Lira | E4: Alejandro Pérez Alcántara | F4: Artista | G4: Terminado | H4: 3 | I4: 46266 | J4: 46283
A5: 1 | B5: S1-02 | C5: 29 | D5: Arte del Espectro de Tinta | E5: Alejandro Pérez Alcántara | F5: Artista | G5: Terminado | H5: 2 | I5: 46266 | J5: 46283
A6: 1 | B6: S1-03 | C6: 29 | D6: Arte de Kaelor, Isolde y Threnody | E6: Alejandro Pérez Alcántara | F6: Artista | G6: Terminado | H6: 4 | I6: 46266 | J6: 46283
A7: 1 | B7: S1-04 | C7: 29 | D7: Los 5 fondos de las alas | E7: Alejandro Pérez Alcántara | F7: Artista | G7: Terminado | H7: 5 | I7: 46266 | J7: 46283
A8: 1 | B8: S1-05 | C8: 29 | D8: Arte de los 6 ítems | E8: Alejandro Pérez Alcántara | F8: Artista | G8: Terminado | H8: 3 | I8: 46266 | J8: 46283
A9: 1 | B9: S1-06 | C9: 29 | D9: Arte de la UI (barras y marcos) | E9: Alejandro Pérez Alcántara | F9: Artista | G9: Terminado | H9: 2 | I9: 46266 | J9: 46283
A10: 1 | B10: S1-07 | C10: 29 | D10: Arte de los 11 enemigos comunes | E10: Alejandro Pérez Alcántara | F10: Artista | G10: Terminado | H10: 12 | I10: 46266 | J10: 46295
A11: 1 | B11: S1-08 | C11: 29 | D11: Limpieza y revisión de las imágenes | E11: Alejandro Pérez Alcántara | F11: Artista | G11: Terminado | H11: 4 | I11: 46266 | J11: 46295
A12: 1 | B12: S1-09 | C12: 29 | D12: Bocetos a lápiz | E12: Alejandro Pérez Alcántara | F12: Artista | G12: Terminado | H12: 3 | I12: 46266 | J12: 46283
A13: 1 | B13: S1-10 | C13: 29 | D13: Revisión y verificación del arte | E13: Alejandro Pérez Alcántara | F13: Artista | G13: Terminado | H13: 2 | I13: 46266 | J13: 46283
A14: 2 | B14: T01 | C14: 15 | D14: Ordenar sprites e importarlos a Unity (ConfigureSprites.cs) | E14: Alejandro Pérez Alcántara | F14: Programador | G14: Terminado | H14: 6 | I14: 46284 | J14: 46295
A15: 2 | B15: T02 | C15: 2 | D15: ScriptableObjects SpellData, ItemData y EnemyData | E15: Alejandro Pérez Alcántara | F15: Programador | G15: Terminado | H15: 4 | I15: 46291 | J15: 46295
... A44: 2 | B44: T31 | C44: 25 | D44: Actualizar el libro de producción con el Sprint 2 | E44: Alejandro Pérez Alcántara | F44: Programador | G44: Terminado | H44: 3 | I44: 46302 | J44: 46302
A45: 2 | B45: T32 | C45: 14 | D45: Pruebas Alfa de las cinco alas (las pendientes se repasan al practicar la demostración) | E45: Alejandro Pérez Alcántara | F45: Programador | G45: En desarrollo | H45: 6 | I45: 46302
A46: 2 | B46: T33 | C46: 24 | D46: Generar el .exe y probarlo en otra computadora | E46: Alejandro Pérez Alcántara | F46: Programador | G46: En desarrollo | H46: 2 | I46: 46308
A47: 2 | B47: T34 | C47: 25 | D47: Documento del Producto 2 en Word y PDF con capturas | E47: Alejandro Pérez Alcántara | F47: Programador | G47: Terminado | H47: 6 | I47: 46302 | J47: 46308
A48: 2 | B48: T35 | C48: 14 | D48: Sprint Review del Sprint 2 | E48: Alejandro Pérez Alcántara | F48: Programador | G48: Planeado | H48: 1
A49: 2 | B49: T36 | C49: 21 | D49: Corregir el acertijo de la caja del Ala de Viento (B-014) | E49: Alejandro Pérez Alcántara | F49: Programador | G49: Terminado | H49: 1 | I49: 46302 | J49: 46302
A50: 2 | B50: T37 | C50: 1 | D50: Corregir a Lira flotando sobre el suelo (B-015) | E50: Alejandro Pérez Alcántara | F50: Programador | G50: Terminado | H50: 2 | I50: 46308 | J50: 46308
A51: 2 | B51: T38 | C51: 20 | D51: Controles de teclado para laptop (J K L, W para apuntar) | E51: Alejandro Pérez Alcántara | F51: Programador | G51: Terminado | H51: 2 | I51: 46308 | J51: 46308
A52: 2 | B52: T39 | C52: 25 | D52: Manual del jugador en PDF | E52: Alejandro Pérez Alcántara | F52: Programador | G52: Terminado | H52: 3 | I52: 46308 | J52: 46308
A53: 2 | B53: T40 | C53: 27 | D53: Ayuda para apuntar: el hechizo sigue al enemigo más cercano a la mira (opción en Opciones) | E53: Alejandro Pérez Alcántara | F53: Programador | G53: Terminado | H53: 3 | I53: 46310 | J53: 46310
A54: 2 | B54: T41 | C54: 10 | D54: Aves de Tormenta: aviso antes de la picada, descanso después y menos empuje (B-016) | E54: Alejandro Pérez Alcántara | F54: Programador | G54: Terminado | H54: 2 | I54: 46310 | J54: 46310
A55: 2 | B55: T42 | C55: 1 | D55: Giro de Lira hacia donde camina con animación (B-017) | E55: Alejandro Pérez Alcántara | F55: Programador | G55: Terminado | H55: 1 | I55: 46310 | J55: 46310
A56: 2 | B56: T43 | C56: 23 | D56: Sentido arcano: chispas, tintineo y aviso cerca de secretos (B-018) | E56: Alejandro Pérez Alcántara | F56: Programador | G56: Terminado | H56: 3 | I56: 46310 | J56: 46310
A57: 2 | B57: T44 | C57: 19 | D57: 12 efectos de sonido nuevos (lanzar, sin maná, quejido, graznido, caídas, latido, etc.) | E57: Alejandro Pérez Alcántara | F57: Programador | G57: Terminado | H57: 2 | I57: 46310 | J57: 46310
A58: 2 | B58: T45 | C58: 27 | D58: Saltar nivel: opción en la pausa y mantener N o L3 + R3 | E58: Alejandro Pérez Alcántara | F58: Programador | G58: Terminado | H58: 2 | I58: 46315 | J58: 46315
A59: 2 | B59: T46 | C59: 24 | D59: Compilar la versión 1.0 del .exe y actualizar el manual | E59: Alejandro Pérez Alcántara | F59: Programador | G59: Terminado | H59: 2 | I59: 46315 | J59: 46315
A60: 2 | B60: T47 | C60: 14 | D60: Fondos con más capas en cada ala (niebla, rayos de luz, estandartes, aves, aurora, libros y velas) | E60: Alejandro Pérez Alcántara | F60: Programador | G60: Terminado | H60: 3 | I60: 46316 | J60: 46316
... A64: 2 | B64: T51 | C64: 25 | D64: Unir todos los sprints en un solo libro de producción | E64: Alejandro Pérez Alcántara | F64: Programador | G64: Terminado | H64: 2 | I64: 46317 | J64: 46317
A65: 2 | B65: T52 | C65: 14 | D65: Preparar y practicar la demostración para la Evaluación Beta (recorrido por las cinco alas con el .exe) | E65: Alejandro Pérez Alcántara | F65: Programador | G65: Planeado | H65: 2 | I65: 46321
A66: 2 | B66: T53 | C66: 14 | D66: Evaluación Beta en clase el miércoles 28 de octubre: demostración jugando frente al profe y al grupo (rúbrica de 8 criterios) | E66: Alejandro Pérez Alcántara | F66: Programador | G66: Planeado | H66: 1 | I66: 46323
A67: 3 | B67: T54 | C67: 26 | D67: Preparar el .exe 1.0, el formato de Pruebas Beta y la carpeta para compartir | E67: Alejandro Pérez Alcántara | F67: Programador | G67: Terminado | H67: 2 | I67: 46315 | J67: 46315
A68: 3 | B68: T55 | C68: 26 | D68: Diagrama de Gantt del proyecto completo | E68: Alejandro Pérez Alcántara | F68: Programador | G68: Terminado | H68: 1 | I68: 46315 | J68: 46315
A69: 3 | B69: T56 | C69: 26 | D69: Borrador del Postmortem con lo que se sabe hasta ahora | E69: Alejandro Pérez Alcántara | F69: Programador | G69: En desarrollo | H69: 3 | I69: 46315
A70: 3 | B70: T57 | C70: 26 | D70: Registrar en el libro los puntos y comentarios de la Evaluación Beta | E70: Alejandro Pérez Alcántara | F70: Programador | G70: Planeado | H70: 1
A71: 3 | B71: T58 | C71: 14 | D71: Pasar al Buglist lo que salga en la Evaluación Beta y darle severidad | E71: Alejandro Pérez Alcántara | F71: Programador | G71: Planeado | H71: 1
...

Sheet Daily Huddle
A1: DAILY HUDDLE - TODOS LOS SPRINTS
A2: Nota: registro por sesión de trabajo (proyecto individual). Las filas sin contenido corresponden a sesiones planificadas.
A3: Sprint | B3: Fecha | C3: ¿Qué hice desde el último Huddle? | D3: ¿Qué haré hoy? | E3: Impedimentos
A4: 2 | B4: 46284 | C4: Sprint Huddle de arranque: cierre del Sprint 1 y revisión del Feature Log. | D4: Ordenar el arte y empezar a importarlo a Unity. | E4: Primera vez armando un proyecto completo en Unity 6.
A5: 2 | B5: 46295 | C5: Sprites ordenados; 15 enemigos y jefes y 12 ítems importados. | D5: Código base: ScriptableObjects, PlayerController, Health, SpellCaster, EnemyBase y GameManager. | E5: Muchos sprites con nombres distintos al GDD; se renombraron.
A6: 2 | B6: 46299 | C6: Código base y Nivel 1 armado con herramienta de editor. | D6: Generar el juego completo (5 alas, jefes, logros, créditos) y probarlo en Unity. | E6: El escenario se veía plano y las barras del HUD no cargaban su imagen (B-001).
A7: 2 | B7: 46300 | C7: Versión 2 con control de PS4, luces 2D y nueva interfaz; historia dentro del juego. | D7: Música, voces, agacharse, niveles más grandes, Opciones, resultados, habilidades 2.11 y acertijos. | E7: Sin sonido (B-003), textos fuera del marco (B-004), final repetido (B-006), portal del Nivel 1 atorado (B-011).
A8: 2 | B8: 46302 | C8: Opciones, resultados, habilidades y nueva fuente subidos al repositorio. | D8: Corregir el final de Elenora, agregar capturas y compilación del .exe, actualizar producción. | E8: El final no terminaba al vencer a Elenora (B-012); el panel de depuración se abría con L3 + R3 (B-013); no se abría el pasadizo del Ala de Viento (B-014).
A9: 2 | B9: 46308 | C9: Producto 2 completo y probado el final del juego. | D9: Corregir a Lira flotando, controles de teclado para laptop, manual del jugador y generar el .exe. | E9: En la revisión de avance en clase se vio que Lira flota sobre el suelo (B-015).
A10: 2 | B10: 46310 | C10: Primer .exe, manual y controles para laptop. Jugué el Ala de Viento con el control de PS4. | D10: Ayuda para apuntar, aves con aviso, giro de Lira, sentido arcano y sonidos nuevos. | E10: Las aves son difíciles de atinar y empujan a Lira al vacío (B-016); Lira no se voltea bien (B-017); no se encuentran los secretos (B-018). Unity se quedaba cargando al abrir el proyecto (se resolvió cerrando procesos).
A11: 2 | B11: 46315 | C11: Mejoras del 15 de octubre probadas; en la revisión en clase el juego gustó. | D11: Saltar nivel para la presentación, versión 1.0 del .exe, manual actualizado y preparar el Sprint 3. | E11: Ninguno.
A12: 2 | B12: 46316 | C12: Saltar nivel, versión 1.0 del .exe y documentos del Sprint 3. | D12: Darle más vida a los fondos de cada ala, compilar el .exe con los fondos nuevos y preparar mis notas para explicar el juego. | E12: La primera compilación falló por falta de memoria; se volvió a compilar.
A13: 2 | B13: 46317 | C13: Fondos nuevos en las cinco alas, .exe compilado otra vez y guía para explicar el juego. | D13: Versión para celular que pidió el profe: botones táctiles, versión web que se instala como app y publicarla en GitHub Pages. | E13: La primera compilación para web tarda porque Unity reimporta todo al cambiar de plataforma.
A14: 2 | B14: 46318 | C14: Versión web publicada en GitHub Pages y ajustada después de probarla en mi celular; todos los sprints en un solo libro de producción. | D14: Revisar el libro de producción completo, planear el Sprint 4 y revisar la rúbrica del profe para las pruebas. | E14: Ninguno.
A15: 2 | B15: 46322
A16: 2 | B16: 46323
A17: 3 | B17: 46326
A18: 3 | B18: 46329
A19: 3 | B19: 46331
A20: 3 | B20: 46333
A21: 3 | B21: 46336
A22: 3 | B22: 46338
A23: 3 | B23: 46340
A24: 3 | B24: 46343
A25: 3 | B25: 46345

Sheet Project Chart
A1: PROJECT CHART - Estado general del proyecto
A2: Nota: fuente, columna Estado del Feature Log.
A3: Estado | B3: Features | C3: Porcentaje
A4: Terminado | B4: =COUNTIF('Feature Log'!$C$4:$C$32,A4) -> 26 | C4: =IF(SUM($B$4:$B$7)=0,0,B4/SUM($B$4:$B$7)) -> 0.89655172
A5: En desarrollo | B5: =COUNTIF('Feature Log'!$C$4:$C$32,A5) -> 3 | C5: =IF(SUM($B$4:$B$7)=0,0,B5/SUM($B$4:$B$7)) -> 0.10344828
A6: Planeado | B6: =COUNTIF('Feature Log'!$C$4:$C$32,A6) -> 0 | C6: =IF(SUM($B$4:$B$7)=0,0,B6/SUM($B$4:$B$7)) -> 0
A7: Sin planear | B7: =COUNTIF('Feature Log'!$C$4:$C$32,A7) -> 0 | C7: =IF(SUM($B$4:$B$7)=0,0,B7/SUM($B$4:$B$7)) -> 0
A8: Total | B8: =SUM(B4:B7) -> 29

Sheet Burn-down Chart
A1: BURN-DOWN CHART - TODOS LOS SPRINTS
A2: Nota: Sprint 1 en tareas restantes (datos del Producto 1). Sprints 2–4 en horas restantes, calculadas desde el Sprint Backlog (Estado = Terminado y Fin ≤ fecha de corte). Las fechas posteriores al día actual no se grafican.
A4: Sprint 1 (1 - 18 sep)
A5: Fecha | B5: Ideal (tareas) | C5: Real (tareas)
A6: 46266 | B6: 10 | C6: 10
A7: 46267 | B7: 9.2 | C7: 9
A8: 46268 | B8: 8.4 | C8: 8
A9: 46269 | B9: 7.6 | C9: 7
A10: 46270 | B10: 6.8 | C10: 6
A11: 46271 | B11: 6 | C11: 5
A12: 46272 | B12: 5.2 | C12: 4
A13: 46273 | B13: 4.4 | C13: 3
A14: 46274 | B14: 3.6 | C14: 2
A15: 46275 | B15: 2.8 | C15: 2
A16: 46276 | B16: 2 | C16: 1
A17: 46277 | B17: 1.2 | C17: 1
A18: 46278 | B18: 0.4 | C18: 0
A24: Sprint 2 (19 sep - 30 oct)
A25: Fecha | B25: Ideal (hrs) | C25: Real (hrs) | D25: Tareas restantes
A26: 46284 | B26: =ROUND('Sprint Backlog'!$G$89*('Sprint Plan'!$D$5-A26)/('Sprint Plan'!$D$5-'Sprint Plan'!$B$5),1) -> 207 | C26: =IF(A26>TODAY(),NA(),'Sprint Backlog'!$G$89-SUMIFS('Sprint Backlog'!$H$4:$H$85,'Sprint Backlog'!$A$4:$A$85,2,'Sprint Backlog'!$G$4:$G$85,"Terminado",'Sprint Backlog'!$J$4:$J$85,"<="&A26)) -> 207 | D26: =IF(A26>TODAY(),NA(),'Sprint Backlog'!$E$89-COUNTIFS('Sprint Backlog'!$A$4:$A$85,2,'Sprint Backlog'!$G$4:$G$85,"Terminado",'Sprint Backlog'!$J$4:$J$85,"<="&A26)) -> 53
A27: 46288 | B27: =ROUND('Sprint Backlog'!$G$89*('Sprint Plan'!$D$5-A27)/('Sprint Plan'!$D$5-'Sprint Plan'!$B$5),1) -> 186.8 | C27: =IF(A27>TODAY(),NA(),'Sprint Backlog'!$G$89-SUMIFS('Sprint Backlog'!$H$4:$H$85,'Sprint Backlog'!$A$4:$A$85,2,'Sprint Backlog'!$G$4:$G$85,"Terminado",'Sprint Backlog'!$J$4:$J$85,"<="&A27)) -> 207 | D27: =IF(A27>TODAY(),NA(),'Sprint Backlog'!$E$89-COUNTIFS('Sprint Backlog'!$A$4:$A$85,2,'Sprint Backlog'!$G$4:$G$85,"Terminado",'Sprint Backlog'!$J$4:$J$85,"<="&A27)) -> 53
A28: 46291 | B28: =ROUND('Sprint Backlog'!$G$89*('Sprint Plan'!$D$5-A28)/('Sprint Plan'!$D$5-'Sprint Plan'!$B$5),1) -> 171.7 | C28: =IF(A28>TODAY(),NA(),'Sprint Backlog'!$G$89-SUMIFS('Sprint Backlog'!$H$4:$H$85,'Sprint Backlog'!$A$4:$A$85,2,'Sprint Backlog'!$G$4:$G$85,"Terminado",'Sprint Backlog'!$J$4:$J$85,"<="&A28)) -> 207 | D28: =IF(A28>TODAY(),NA(),'Sprint Backlog'!$E$89-COUNTIFS('Sprint Backlog'!$A$4:$A$85,2,'Sprint Backlog'!$G$4:$G$85,"Terminado",'Sprint Backlog'!$J$4:$J$85,"<="&A28)) -> 53
A29: 46295 | B29: =ROUND('Sprint Backlog'!$G$89*('Sprint Plan'!$D$5-A29)/('Sprint Plan'!$D$5-'Sprint Plan'!$B$5),1) -> 151.5 | C29: =IF(A29>TODAY(),NA(),'Sprint Backlog'!$G$89-SUMIFS('Sprint Backlog'!$H$4:$H$85,'Sprint Backlog'!$A$4:$A$85,2,'Sprint Backlog'!$G$4:$G$85,"Terminado",'Sprint Backlog'!$J$4:$J$85,"<="&A29)) -> 169 | D29: =IF(A29>TODAY(),NA(),'Sprint Backlog'!$E$89-COUNTIFS('Sprint Backlog'!$A$4:$A$85,2,'Sprint Backlog'!$G$4:$G$85,"Terminado",'Sprint Backlog'!$J$4:$J$85,"<="&A29)) -> 46
A30: 46299 | B30: =ROUND('Sprint Backlog'!$G$89*('Sprint Plan'!$D$5-A30)/('Sprint Plan'!$D$5-'Sprint Plan'!$B$5),1) -> 131.3 | C30: =IF(A30>TODAY(),NA(),'Sprint Backlog'!$G$89-SUMIFS('Sprint Backlog'!$H$4:$H$85,'Sprint Backlog'!$A$4:$A$85,2,'Sprint Backlog'!$G$4:$G$85,"Terminado",'Sprint Backlog'!$J$4:$J$85,"<="&A30)) -> 116 | D30: =IF(A30>TODAY(),NA(),'Sprint Backlog'!$E$89-COUNTIFS('Sprint Backlog'!$A$4:$A$85,2,'Sprint Backlog'!$G$4:$G$85,"Terminado",'Sprint Backlog'!$J$4:$J$85,"<="&A30)) -> 37
A31: 46300 | B31: =ROUND('Sprint Backlog'!$G$89*('Sprint Plan'!$D$5-A31)/('Sprint Plan'!$D$5-'Sprint Plan'!$B$5),1) -> 126.2 | C31: =IF(A31>TODAY(),NA(),'Sprint Backlog'!$G$89-SUMIFS('Sprint Backlog'!$H$4:$H$85,'Sprint Backlog'!$A$4:$A$85,2,'Sprint Backlog'!$G$4:$G$85,"Terminado",'Sprint Backlog'!$J$4:$J$85,"<="&A31)) -> 66 | D31: =IF(A31>TODAY(),NA(),'Sprint Backlog'!$E$89-COUNTIFS('Sprint Backlog'!$A$4:$A$85,2,'Sprint Backlog'!$G$4:$G$85,"Terminado",'Sprint Backlog'!$J$4:$J$85,"<="&A31)) -> 25
A32: 46302 | B32: =ROUND('Sprint Backlog'!$G$89*('Sprint Plan'!$D$5-A32)/('Sprint Plan'!$D$5-'Sprint Plan'!$B$5),1) -> 116.1 | C32: =IF(A32>TODAY(),NA(),'Sprint Backlog'!$G$89-SUMIFS('Sprint Backlog'!$H$4:$H$85,'Sprint Backlog'!$A$4:$A$85,2,'Sprint Backlog'!$G$4:$G$85,"Terminado",'Sprint Backlog'!$J$4:$J$85,"<="&A32)) -> 57 | D32: =IF(A32>TODAY(),NA(),'Sprint Backlog'!$E$89-COUNTIFS('Sprint Backlog'!$A$4:$A$85,2,'Sprint Backlog'!$G$4:$G$85,"Terminado",'Sprint Backlog'!$J$4:$J$85,"<="&A32)) -> 21
A33: 46308 | B33: =ROUND('Sprint Backlog'!$G$89*('Sprint Plan'!$D$5-A33)/('Sprint Plan'!$D$5-'Sprint Plan'!$B$5),1) -> 85.8 | C33: =IF(A33>TODAY(),NA(),'Sprint Backlog'!$G$89-SUMIFS('Sprint Backlog'!$H$4:$H$85,'Sprint Backlog'!$A$4:$A$85,2,'Sprint Backlog'!$G$4:$G$85,"Terminado",'Sprint Backlog'!$J$4:$J$85,"<="&A33)) -> 44 | D33: =IF(A33>TODAY(),NA(),'Sprint Backlog'!$E$89-COUNTIFS('Sprint Backlog'!$A$4:$A$85,2,'Sprint Backlog'!$G$4:$G$85,"Terminado",'Sprint Backlog'!$J$4:$J$85,"<="&A33)) -> 17
A34: 46310 | B34: =ROUND('Sprint Backlog'!$G$89*('Sprint Plan'!$D$5-A34)/('Sprint Plan'!$D$5-'Sprint Plan'!$B$5),1) -> 75.7 | C34: =IF(A34>TODAY(),NA(),'Sprint Backlog'!$G$89-SUMIFS('Sprint Backlog'!$H$4:$H$85,'Sprint Backlog'!$A$4:$A$85,2,'Sprint Backlog'!$G$4:$G$85,"Terminado",'Sprint Backlog'!$J$4:$J$85,"<="&A34)) -> 33 | D34: =IF(A34>TODAY(),NA(),'Sprint Backlog'!$E$89-COUNTIFS('Sprint Backlog'!$A$4:$A$85,2,'Sprint Backlog'!$G$4:$G$85,"Terminado",'Sprint Backlog'!$J$4:$J$85,"<="&A34)) -> 12
A35: 46316 | B35: =ROUND('Sprint Backlog'!$G$89*('Sprint Plan'!$D$5-A35)/('Sprint Plan'!$D$5-'Sprint Plan'!$B$5),1) -> 45.4 | C35: =IF(A35>TODAY(),NA(),'Sprint Backlog'!$G$89-SUMIFS('Sprint Backlog'!$H$4:$H$85,'Sprint Backlog'!$A$4:$A$85,2,'Sprint Backlog'!$G$4:$G$85,"Terminado",'Sprint Backlog'!$J$4:$J$85,"<="&A35)) -> 24 | D35: =IF(A35>TODAY(),NA(),'Sprint Backlog'!$E$89-COUNTIFS('Sprint Backlog'!$A$4:$A$85,2,'Sprint Backlog'!$G$4:$G$85,"Terminado",'Sprint Backlog'!$J$4:$J$85,"<="&A35)) -> 8
A36: 46317 | B36: =ROUND('Sprint Backlog'!$G$89*('Sprint Plan'!$D$5-A36)/('Sprint Plan'!$D$5-'Sprint Plan'!$B$5),1) -> 40.4 | C36: =IF(A36>TODAY(),NA(),'Sprint Backlog'!$G$89-SUMIFS('Sprint Backlog'!$H$4:$H$85,'Sprint Backlog'!$A$4:$A$85,2,'Sprint Backlog'!$G$4:$G$85,"Terminado",'Sprint Backlog'!$J$4:$J$85,"<="&A36)) -> 16 | D36: =IF(A36>TODAY(),NA(),'Sprint Backlog'!$E$89-COUNTIFS('Sprint Backlog'!$A$4:$A$85,2,'Sprint Backlog'!$G$4:$G$85,"Terminado",'Sprint Backlog'!$J$4:$J$85,"<="&A36)) -> 6
A37: 46318 | B37: =ROUND('Sprint Backlog'!$G$89*('Sprint Plan'!$D$5-A37)/('Sprint Plan'!$D$5-'Sprint Plan'!$B$5),1) -> 35.3 | C37: =IF(A37>TODAY(),NA(),'Sprint Backlog'!$G$89-SUMIFS('Sprint Backlog'!$H$4:$H$85,'Sprint Backlog'!$A$4:$A$85,2,'Sprint Backlog'!$G$4:$G$85,"Terminado",'Sprint Backlog'!$J$4:$J$85,"<="&A37)) -> 12 | D37: =IF(A37>TODAY(),NA(),'Sprint Backlog'!$E$89-COUNTIFS('Sprint Backlog'!$A$4:$A$85,2,'Sprint Backlog'!$G$4:$G$85,"Terminado",'Sprint Backlog'!$J$4:$J$85,"<="&A37)) -> 5
... A40: 46325 | B40: =ROUND('Sprint Backlog'!$G$89*('Sprint Plan'!$D$5-A40)/('Sprint Plan'!$D$5-'Sprint Plan'!$B$5),1) -> 0 | C40: =IF(A40>TODAY(),NA(),'Sprint Backlog'!$G$89-SUMIFS('Sprint Backlog'!$H$4:$H$85,'Sprint Backlog'!$A$4:$A$85,2,'Sprint Backlog'!$G$4:$G$85,"Terminado",'Sprint Backlog'!$J$4:$J$85,"<="&A40)) -> #N/A | D40: =IF(A40>TODAY(),NA(),'Sprint Backlog'!$E$89-COUNTIFS('Sprint Backlog'!$A$4:$A$85,2,'Sprint Backlog'!$G$4:$G$85,"Terminado",'Sprint Backlog'!$J$4:$J$85,"<="&A40)) -> #N/A
A44: Sprint 3 (31 oct - 20 nov)
A45: Fecha | B45: Ideal (hrs) | C45: Real (hrs) | D45: Tareas restantes
A46: 46326 | B46: =ROUND('Sprint Backlog'!$G$90*('Sprint Plan'!$D$6-A46)/('Sprint Plan'!$D$6-'Sprint Plan'!$B$6),1) -> 27 | C46: =IF(A46>TODAY(),NA(),'Sprint Backlog'!$G$90-SUMIFS('Sprint Backlog'!$H$4:$H$85,'Sprint Backlog'!$A$4:$A$85,3,'Sprint Backlog'!$G$4:$G$85,"Terminado",'Sprint Backlog'!$J$4:$J$85,"<="&A46)) -> #N/A | D46: =IF(A46>TODAY(),NA(),'Sprint Backlog'!$E$90-COUNTIFS('Sprint Backlog'!$A$4:$A$85,3,'Sprint Backlog'!$G$4:$G$85,"Terminado",'Sprint Backlog'!$J$4:$J$85,"<="&A46)) -> #N/A
A47: 46329 | B47: =ROUND('Sprint Backlog'!$G$90*('Sprint Plan'!$D$6-A47)/('Sprint Plan'!$D$6-'Sprint Plan'!$B$6),1) -> 23 | C47: =IF(A47>TODAY(),NA(),'Sprint Backlog'!$G$90-SUMIFS('Sprint Backlog'!$H$4:$H$85,'Sprint Backlog'!$A$4:$A$85,3,'Sprint Backlog'!$G$4:$G$85,"Terminado",'Sprint Backlog'!$J$4:$J$85,"<="&A47)) -> #N/A | D47: =IF(A47>TODAY(),NA(),'Sprint Backlog'!$E$90-COUNTIFS('Sprint Backlog'!$A$4:$A$85,3,'Sprint Backlog'!$G$4:$G$85,"Terminado",'Sprint Backlog'!$J$4:$J$85,"<="&A47)) -> #N/A
A48: 46331 | B48: =ROUND('Sprint Backlog'!$G$90*('Sprint Plan'!$D$6-A48)/('Sprint Plan'!$D$6-'Sprint Plan'!$B$6),1) -> 20.3 | C48: =IF(A48>TODAY(),NA(),'Sprint Backlog'!$G$90-SUMIFS('Sprint Backlog'!$H$4:$H$85,'Sprint Backlog'!$A$4:$A$85,3,'Sprint Backlog'!$G$4:$G$85,"Terminado",'Sprint Backlog'!$J$4:$J$85,"<="&A48)) -> #N/A | D48: =IF(A48>TODAY(),NA(),'Sprint Backlog'!$E$90-COUNTIFS('Sprint Backlog'!$A$4:$A$85,3,'Sprint Backlog'!$G$4:$G$85,"Terminado",'Sprint Backlog'!$J$4:$J$85,"<="&A48)) -> #N/A
A49: 46333 | B49: =ROUND('Sprint Backlog'!$G$90*('Sprint Plan'!$D$6-A49)/('Sprint Plan'!$D$6-'Sprint Plan'!$B$6),1) -> 17.6 | C49: =IF(A49>TODAY(),NA(),'Sprint Backlog'!$G$90-SUMIFS('Sprint Backlog'!$H$4:$H$85,'Sprint Backlog'!$A$4:$A$85,3,'Sprint Backlog'!$G$4:$G$85,"Terminado",'Sprint Backlog'!$J$4:$J$85,"<="&A49)) -> #N/A | D49: =IF(A49>TODAY(),NA(),'Sprint Backlog'!$E$90-COUNTIFS('Sprint Backlog'!$A$4:$A$85,3,'Sprint Backlog'!$G$4:$G$85,"Terminado",'Sprint Backlog'!$J$4:$J$85,"<="&A49)) -> #N/A
A50: 46336 | B50: =ROUND('Sprint Backlog'!$G$90*('Sprint Plan'!$D$6-A50)/('Sprint Plan'!$D$6-'Sprint Plan'!$B$6),1) -> 13.5 | C50: =IF(A50>TODAY(),NA(),'Sprint Backlog'!$G$90-SUMIFS('Sprint Backlog'!$H$4:$H$85,'Sprint Backlog'!$A$4:$A$85,3,'Sprint Backlog'!$G$4:$G$85,"Terminado",'Sprint Backlog'!$J$4:$J$85,"<="&A50)) -> #N/A | D50: =IF(A50>TODAY(),NA(),'Sprint Backlog'!$E$90-COUNTIFS('Sprint Backlog'!$A$4:$A$85,3,'Sprint Backlog'!$G$4:$G$85,"Terminado",'Sprint Backlog'!$J$4:$J$85,"<="&A50)) -> #N/A
A51: 46338 | B51: =ROUND('Sprint Backlog'!$G$90*('Sprint Plan'!$D$6-A51)/('Sprint Plan'!$D$6-'Sprint Plan'!$B$6),1) -> 10.8 | C51: =IF(A51>TODAY(),NA(),'Sprint Backlog'!$G$90-SUMIFS('Sprint Backlog'!$H$4:$H$85,'Sprint Backlog'!$A$4:$A$85,3,'Sprint Backlog'!$G$4:$G$85,"Terminado",'Sprint Backlog'!$J$4:$J$85,"<="&A51)) -> #N/A | D51: =IF(A51>TODAY(),NA(),'Sprint Backlog'!$E$90-COUNTIFS('Sprint Backlog'!$A$4:$A$85,3,'Sprint Backlog'!$G$4:$G$85,"Terminado",'Sprint Backlog'!$J$4:$J$85,"<="&A51)) -> #N/A
...

Sheet Task Chart
A1: TASK CHART - TODOS LOS SPRINTS
A2: Nota: Sprint 1 con datos del Producto 1; Sprints 2–4 calculados desde la hoja Burn-down Chart.
A4: Sprint 1 (1 - 18 sep)
A5: Fecha | B5: Terminadas | C5: En progreso
A6: 46266 | B6: 1 | C6: 3
A7: 46267 | B7: 2 | C7: 2
A8: 46268 | B8: 3 | C8: 2
A9: 46269 | B9: 4 | C9: 2
A10: 46270 | B10: 5 | C10: 2
A11: 46271 | B11: 6 | C11: 2
A12: 46272 | B12: 7 | C12: 2
A13: 46273 | B13: 8 | C13: 1
A14: 46274 | B14: 9 | C14: 1
A15: 46275 | B15: 9 | C15: 1
A16: 46276 | B16: 9 | C16: 1
A17: 46277 | B17: 10 | C17: 0
A24: Sprint 2 (19 sep - 30 oct)
A25: Fecha | B25: Tareas restantes | C25: Terminadas
A26: ='Burn-down Chart'!A26 -> 46284 | B26: ='Burn-down Chart'!D26 -> 53 | C26: =IF(ISNA(B26),NA(),'Sprint Backlog'!$E$89-B26) -> 0
A27: ='Burn-down Chart'!A27 -> 46288 | B27: ='Burn-down Chart'!D27 -> 53 | C27: =IF(ISNA(B27),NA(),'Sprint Backlog'!$E$89-B27) -> 0
A28: ='Burn-down Chart'!A28 -> 46291 | B28: ='Burn-down Chart'!D28 -> 53 | C28: =IF(ISNA(B28),NA(),'Sprint Backlog'!$E$89-B28) -> 0
A29: ='Burn-down Chart'!A29 -> 46295 | B29: ='Burn-down Chart'!D29 -> 46 | C29: =IF(ISNA(B29),NA(),'Sprint Backlog'!$E$89-B29) -> 7
A30: ='Burn-down Chart'!A30 -> 46299 | B30: ='Burn-down Chart'!D30 -> 37 | C30: =IF(ISNA(B30),NA(),'Sprint Backlog'!$E$89-B30) -> 16
A31: ='Burn-down Chart'!A31 -> 46300 | B31: ='Burn-down Chart'!D31 -> 25 | C31: =IF(ISNA(B31),NA(),'Sprint Backlog'!$E$89-B31) -> 28
A32: ='Burn-down Chart'!A32 -> 46302 | B32: ='Burn-down Chart'!D32 -> 21 | C32: =IF(ISNA(B32),NA(),'Sprint Backlog'!$E$89-B32) -> 32
A33: ='Burn-down Chart'!A33 -> 46308 | B33: ='Burn-down Chart'!D33 -> 17 | C33: =IF(ISNA(B33),NA(),'Sprint Backlog'!$E$89-B33) -> 36
A34: ='Burn-down Chart'!A34 -> 46310 | B34: ='Burn-down Chart'!D34 -> 12 | C34: =IF(ISNA(B34),NA(),'Sprint Backlog'!$E$89-B34) -> 41
A35: ='Burn-down Chart'!A35 -> 46316 | B35: ='Burn-down Chart'!D35 -> 8 | C35: =IF(ISNA(B35),NA(),'Sprint Backlog'!$E$89-B35) -> 45
A36: ='Burn-down Chart'!A36 -> 46317 | B36: ='Burn-down Chart'!D36 -> 6 | C36: =IF(ISNA(B36),NA(),'Sprint Backlog'!$E$89-B36) -> 47
A37: ='Burn-down Chart'!A37 -> 46318 | B37: ='Burn-down Chart'!D37 -> 5 | C37: =IF(ISNA(B37),NA(),'Sprint Backlog'!$E$89-B37) -> 48
... A40: ='Burn-down Chart'!A40 -> 46325 | B40: ='Burn-down Chart'!D40 -> #N/A | C40: =IF(ISNA(B40),NA(),'Sprint Backlog'!$E$89-B40) -> #N/A
A44: Sprint 3 (31 oct - 20 nov)
A45: Fecha | B45: Tareas restantes | C45: Terminadas
A46: ='Burn-down Chart'!A46 -> 46326 | B46: ='Burn-down Chart'!D46 -> #N/A | C46: =IF(ISNA(B46),NA(),'Sprint Backlog'!$E$90-B46) -> #N/A
A47: ='Burn-down Chart'!A47 -> 46329 | B47: ='Burn-down Chart'!D47 -> #N/A | C47: =IF(ISNA(B47),NA(),'Sprint Backlog'!$E$90-B47) -> #N/A
A48: ='Burn-down Chart'!A48 -> 46331 | B48: ='Burn-down Chart'!D48 -> #N/A | C48: =IF(ISNA(B48),NA(),'Sprint Backlog'!$E$90-B48) -> #N/A
A49: ='Burn-down Chart'!A49 -> 46333 | B49: ='Burn-down Chart'!D49 -> #N/A | C49: =IF(ISNA(B49),NA(),'Sprint Backlog'!$E$90-B49) -> #N/A
A50: ='Burn-down Chart'!A50 -> 46336 | B50: ='Burn-down Chart'!D50 -> #N/A | C50: =IF(ISNA(B50),NA(),'Sprint Backlog'!$E$90-B50) -> #N/A
A51: ='Burn-down Chart'!A51 -> 46338 | B51: ='Burn-down Chart'!D51 -> #N/A | C51: =IF(ISNA(B51),NA(),'Sprint Backlog'!$E$90-B51) -> #N/A
A52: ='Burn-down Chart'!A52 -> 46340 | B52: ='Burn-down Chart'!D52 -> #N/A | C52: =IF(ISNA(B52),NA(),'Sprint Backlog'!$E$90-B52) -> #N/A
...

Sheet Buglist
A1: BUGLIST - TODOS LOS SPRINTS
A2: Nota: campos según la plantilla Huddle (GDD 3.6). Origen: Sprint 1, revisión de arte; Sprint 2, pruebas Alfa (B-001–B-018); Sprint 3, hallazgos de la Evaluación Beta. Severidad: Alta / Media / Baja.
A3: Sprint | B3: BugID | C3: Descripción | D3: Descripción técnica | E3: Autor | F3: Estado | G3: Featureid | H3: Reportado | I3: Severidad
A4: 1 | B4: S1-B1 | C4: Algunos enemigos del arte conceptual tienen un estilo distinto al resto. | D4: Se revisó al importar el arte; algunos quedaron más detallados que otros (lo menciono en el Postmortem). | E4: Alejandro Pérez Alcántara | F4: Por verificar | G4: 29 | H4: 46275 | I4: Media
A5: 1 | B5: S1-B2 | C5: Había que ajustar las proporciones de algunas imágenes. | D5: Se recortaron y se renombraron al importarlas (T01); el espacio transparente de Lira se corrigió en B-015. | E5: Alejandro Pérez Alcántara | F5: Corregido | G5: 29 | H5: 46277 | I5: Baja
A6: 1 | B6: S1-B3 | C6: Los marcos de la UI necesitaban rediseño para verse iguales. | D6: Se cambiaron por paneles 9-slice (B-004). | E6: Alejandro Pérez Alcántara | F6: Corregido | G6: 29 | H6: 46279 | I6: Baja
A7: 2 | B7: B-001 | C7: El escenario se veía plano y las barras del HUD no mostraban su imagen. | D7: Los sprites de la UI no estaban asignados en el prefab del HUD y los fondos no tenían capas. | E7: Alejandro Pérez Alcántara | F7: Corregido | G7: 15 | H7: 46299 | I7: Media
A8: 2 | B8: B-002 | C8: Faltaban imágenes de la interfaz y las columnas del fondo. | D8: Nombres de archivo distintos entre la carpeta Sprites y las rutas de CrearJuego.cs. | E8: Alejandro Pérez Alcántara | F8: Corregido | G8: 14 | H8: 46300 | I8: Baja
A9: 2 | B9: B-003 | C9: No se escuchaba la música ni los efectos. | D9: Ninguna cámara tenía AudioListener. El AudioManager ahora agrega el suyo y quita los de las cámaras. | E9: Alejandro Pérez Alcántara | F9: Corregido | G9: 19 | H9: 46300 | I9: Alta
A10: 2 | B10: B-004 | C10: Los textos de Controles y Logros se salían del marco. | D10: El marco ornamentado se estiraba como imagen simple; se cambió por un panel 9-slice (PanelUI). | E10: Alejandro Pérez Alcántara | F10: Corregido | G10: 15 | H10: 46300 | I10: Media
A11: 2 | B11: B-005 | C11: El retrato de Lira en el HUD se veía mal dentro del marco. | D11: El sprite completo se mostraba encima del marco; se agregó una máscara circular. | E11: Alejandro Pérez Alcántara | F11: Corregido | G11: 17 | H11: 46300 | I11: Baja
A12: 2 | B12: B-006 | C12: Al vencer a Elenora se repetía la batalla final y no salían los créditos. | D12: "Continuar" guardaba el Nivel 5 y no había transición al epílogo; se agregó FinishGame(). | E12: Alejandro Pérez Alcántara | F12: Corregido | G12: 11 | H12: 46300 | I12: Alta
A13: 2 | B13: B-007 | C13: Los créditos tardaban unos 15 segundos en aparecer. | D13: El texto empezaba en y = -900, fuera de la pantalla; ahora empieza visible. | E13: Alejandro Pérez Alcántara | F13: Corregido | G13: 18 | H13: 46300 | I13: Media
A14: 2 | B14: B-008 | C14: El Modo Archimaga a veces no se activaba. | D14: Cualquier otra tecla reiniciaba la secuencia; ahora solo cuentan las teclas del código. | E14: Alejandro Pérez Alcántara | F14: Corregido | G14: 13 | H14: 46300 | I14: Baja
A15: 2 | B15: B-009 | C15: Las voces de los personajes sonaban raras y fuertes. | D15: Síntesis con demasiada aspereza; se suavizó y se bajó el volumen. | E15: Alejandro Pérez Alcántara | F15: Corregido | G15: 19 | H15: 46300 | I15: Baja
... A24: 2 | B24: B-018 | C24: No se sabe dónde están las Páginas Perdidas ni los secretos. | D24: No había ninguna pista cerca de ellos. SentidoArcano.cs muestra chispas, un tintineo y un aviso a menos de 7 unidades. | E24: Alejandro Pérez Alcántara | F24: Corregido | G24: 23 | H24: 46310 | I24: Media
A25: 3 | B25: B-019
A26: 3 | B26: B-020
A27: 3 | B27: B-021
A28: 3 | B28: B-022
A29: 3 | B29: B-023
A30: 3 | B30: B-024
A31: 3 | B31: B-025
A32: 3 | B32: B-026
A33: 3 | B33: B-027
A34: 3 | B34: B-028
A35: 3 | B35: B-029
A36: 3 | B36: B-030
... A39: 3 | B39: B-033
E41: Corregidos: | F41: =COUNTIF(F4:F39,"Corregido")&" de "&COUNTA(C4:C39) -> 19 de 21

Sheet Pruebas Alfa
A1: PRUEBAS ALFA - SPRINT 2
A2: Nota: pruebas internas por versión (fase de Producción). Las fallas se registran en el Buglist con su BugID.
A3: ID | B3: Featureid | C3: Caso de prueba | D3: Pasos | E3: Resultado esperado | F3: Resultado obtenido | G3: Estado
A4: PA-01 | B4: 2 | C4: Costo de maná y recarga de cada hechizo | D4: Lanzar el mismo hechizo varias veces seguidas. | E4: No se lanza sin maná suficiente ni antes de que termine la recarga. | F4: Se respeta el costo y la recarga. | G4: Aprobada
A5: PA-02 | B5: 4 | C5: Los hechizos solo dañan lo que tiene IDamageable | D5: Disparar a paredes, plataformas y enemigos. | E5: Solo los enemigos y objetos rompibles reciben daño. | F5: Correcto. | G5: Aprobada
A6: PA-03 | B6: 3 | C6: IA cambia entre patrulla y persecución | D6: Acercarse y alejarse de un Espectro de tinta. | E6: Patrulla lejos de Lira y la persigue dentro de su rango. | F6: Correcto. | G6: Aprobada
A7: PA-04 | B7: 20 | C7: Control de PS4 por Bluetooth | D7: Jugar el Nivel 1 completo solo con el control. | E7: Todas las acciones responden y el control vibra al recibir daño. | F7: Correcto. | G7: Aprobada
A8: PA-05 | B8: 19 | C8: Música y efectos al iniciar | D8: Abrir el juego desde el menú principal. | E8: Se escucha la música del menú y los sonidos de los botones. | F8: Sin sonido (B-003). Corregido. | G8: Aprobada
A9: PA-06 | B9: 17 | C9: Cambio de nivel con pantalla de resultados | D9: Terminar el Nivel 1 y entrar al portal. | E9: Aparece la pantalla de resultados y luego carga el Nivel 2. | F9: Se quedaba atorado (B-011). Corregido. | G9: Aprobada
A10: PA-07 | B10: 13 | C10: Modo Archimaga | D10: Escribir F, H, V, A y Enter; con control L1 + R1 + Triángulo. | E10: Aparece el aviso y Lira no gasta maná ni recibe daño. | F10: Fallaba a veces (B-008). Corregido. | G10: Aprobada
A11: PA-08 | B11: 16 | C11: Pantalla de Opciones | D11: Cambiar volúmenes, pantalla completa y vibración; salir y volver a entrar. | E11: Los cambios se aplican y se guardan. | F11: Funciona en el editor. | G11: Aprobada
A12: PA-09 | B12: 21 | C12: Fuego quema las zarzas | D12: Lanzar Arcano y luego Fuego a las zarzas del Ala de Fuego. | E12: Solo el Fuego las quema y se abre el pasadizo. | G12: Pendiente
A13: PA-10 | B13: 21 | C13: Hielo congela al tercer golpe | D13: Pegarle tres veces seguidas con Hielo a un enemigo. | E13: El enemigo se pinta de azul y no se mueve por 2.5 s. | G13: Pendiente
A14: PA-11 | B14: 21 | C14: Viento: planear y empujar la caja | D14: Mantener saltar al caer; empujar la caja del Ala de Viento hasta la placa. | E14: Lira cae lento; la caja abre la puerta rúnica. | F14: No se podía abrir (B-014). Corregido, falta probar. | G14: Pendiente
A15: PA-12 | B15: 11 | C15: Final del juego | D15: Derrotar al Eco de Elenora y leer su diálogo. | E15: ¡VICTORIA!, epílogo y créditos; al final regresa al menú. | F15: No terminaba (B-012). Corregido: sale ¡VICTORIA!, epílogo y créditos. | G15: Aprobada
A16: PA-13 | B16: 23 | C16: Páginas Perdidas y salas secretas | D16: Recoger las 3 páginas del Nivel 1 y romper un muro agrietado. | E16: Cada página da +5 de vida máxima; el muro revela la sala. | G16: Pendiente
A17: PA-14 | B17: 24 | C17: Build .exe | D17: Compilar con el menú Ecos del Grimorio y abrir el .exe. | E17: El juego abre en pantalla completa y se puede jugar de inicio a fin. | F17: Compila sin errores (150 MB). Falta probarlo en otra computadora. | G17: Pendiente
A18: PA-15 | B18: 1 | C18: Lira pisa el suelo | D18: Caminar y detenerse sobre el suelo y las plataformas de cada ala. | E18: Los pies de Lira tocan la superficie, sin espacio. | F18: Flotaba (B-015). Corregido. | G18: Aprobada
A19: PA-16 | B19: 27 | C19: Saltar nivel | D19: En cada ala mantener N (o L3 + R3) 1.5 s, y probar Pausa > Saltar nivel. | E19: Pasa a la siguiente ala con el hechizo que tocaba; en el Corazón pasa al final. No da logros. | G19: Pendiente
A20: PA-17 | B20: 27 | C20: Ayuda para apuntar | D20: Disparar a las Aves de Tormenta con y sin la opción activada. | E20: Con la opción, el hechizo sigue al ave; sin ella, va en línea recta. | G20: Pendiente
F22: Aprobadas: | G22: =COUNTIF(G4:G20,"Aprobada")&" de "&COUNTA(A4:A20) -> 10 de 17

Sheet Evaluación Beta
A1: EVALUACIÓN BETA - MATRIZ DE CUMPLIMIENTO
A2: Nota: rúbrica del docente, 8 criterios de 10 puntos. Evidencia verificable en la versión 1.0. Modalidad: demostración en clase, 28/10/2026. El puntaje se registra al concluir la evaluación.
A3: ID | B3: Criterio | C3: Requisito (10 pts) | D3: Evidencia | E3: Referencia | F3: Máx. | G3: Obtenido | H3: Observaciones
A4: EB-01 | B4: Documentación y planeación | C4: Documento detallado y actualizado; cronograma con seguimiento real y cumplimiento de hitos de la fase Beta. | D4: GDD (Producto 1), documento del Producto 2, manual del jugador y libro de producción con 4 sprints, Gantt, Burn-down y Daily Huddle. | E4: Documentacion/; hojas Gantt, Burn-down Chart; BITACORA.md | F4: 10
A5: EB-02 | B5: Contenido y niveles | C5: Flujo completo (menú, niveles con condición de victoria y derrota) y diseño de niveles estructurado. | D5: Menú → prólogo → 5 alas → jefe final → epílogo → créditos. Derrota con reintento; resultados al completar cada ala; dificultad progresiva. | E5: Escenas MenuPrincipal, Prologo, Nivel1_* a Nivel5_*, Epilogo, Creditos; GameManager.cs | F5: 10
A6: EB-03 | B6: Arte, audio e interfaz (UI/UX) | C6: Apartado visual y sonoro coherente con la propuesta; UI intuitiva y con respuesta correcta. | D6: Arte basado en los bocetos del GDD, parallax, iluminación 2D; 9 pistas, 41 efectos y voces; HUD, pausa y opciones con indicaciones según el dispositivo. | E6: Assets/Sprites, Assets/Audio; AudioManager.cs, UIManager.cs, HUD.cs, OpcionesUI.cs | F6: 10
A7: EB-04 | B7: Respuesta de eventos (mecánica) | C7: La interacción de los personajes responde a los eventos según la funcionalidad del juego. | D7: Movimiento, salto, planeo, esquive; 4 hechizos y 4 combos; IA de patrulla y persecución; daño elemental; objetos rompibles, empujables, cofres y diálogos. | E7: PlayerController.cs, SpellCaster.cs, EnemyBase.cs, Health.cs, Rompible.cs, Empujable.cs | F7: 10
A8: EB-05 | B8: Jugabilidad | C8: Se cumplen las acciones de la historia (inicio, desarrollo y cierre) y es posible completar el juego. | D8: Inicio: prólogo. Desarrollo: un hechizo y un guardián por ala. Cierre: Eco de Elenora, epílogo y créditos. | E8: Prologo.cs, LevelExit.cs, BossController.cs, ElenoraBoss.cs, CreditsScreen.cs | F8: 10
A9: EB-06 | B9: Niveles | C9: Al menos un nivel donde se desarrolla la historia completa. | D9: Cinco niveles enlazados con la narrativa (Aprendizaje, Fuego, Hielo, Viento y Corazón del Grimorio), cada uno con guardián. | E9: CrearJuego.cs; escenas Nivel1_* a Nivel5_* | F9: 10
A10: EB-07 | B10: Elementos gráficos | C10: Los elementos gráficos dan soporte al desarrollo completo de la historia. | D10: 3 personajes, 4 guardianes, 13 tipos de enemigos, ítems, armas, fondos por ala y elementos de interfaz. | E10: Assets/Sprites; Arte/ (repositorio) | F10: 10
A11: EB-08 | B11: Ejecución | C11: El juego se ejecuta directamente como aplicación y sin contratiempos. | D11: Ejecutable para Windows x64 independiente del editor; versión WebGL instalable como PWA. | E11: EcosDelGrimorio_v1.zip; alexap1115web.github.io/Ecos-Del-Grimorio | F11: 10
E12: Total | F12: =SUM(F4:F11) -> 80 | G12: =IF(COUNT(G4:G11)=0,"",SUM(G4:G11))
A14: PRUEBAS DE COMPATIBILIDAD
A15: ID | B15: Fecha | C15: Plataforma / build | D15: Dispositivo / SO | E15: Probador | F15: Resultado | H15: Observaciones
A16: PC-01 | B16: 46317 | C16: Web (WebGL), versión 1.0 | D16: Smartphone Android, Chrome | E16: Desarrollador | F16: Con observaciones | H16: Texto inferior del menú recortado en pantalla 20:9; truco táctil de tres toques no detectado. Corregido con AjustePantalla.cs y truco Combo + Cambiar.
A17: PC-02 | B17: 46318 | C17: Web (WebGL), versión 1.0 | D17: Smartphone | E17: Usuario externo | F17: Aprobada | H17: Carga y partida sin fallas.
A18: PC-03 | C18: Windows (.exe), versión 1.0 | D18: Equipo externo, Windows 10/11 x64 | F18: Pendiente
A19: PC-04 | C19: Web (WebGL), versión 1.0 | D19: Equipo externo, Chrome / Edge | F19: Pendiente

Sheet Matriz GDD
A1: COHERENCIA ENTRE EL GDD Y EL BACKLOG
A2: Nota: trazabilidad requisito del GDD → feature → tarea. El estado corresponde al primer feature listado.
A3: Sección GDD | B3: Requisito del documento de diseño | C3: Featureid | D3: Tareas | E3: Estado
A4: 2.1 / 2.3 | B4: Acertijos ambientales; cada hechizo abre rutas bloqueadas | C4: 21 | D4: T27 | E4: =IFERROR(INDEX('Feature Log'!$C$4:$C$32,MATCH(VALUE(LEFT(C4,FIND(",",C4&",")-1)),'Feature Log'!$A$4:$A$32,0)),"") -> Terminado
A5: 2.4 | B5: Cámara lateral con seguimiento suave | C5: 1 | D5: T03 | E5: =IFERROR(INDEX('Feature Log'!$C$4:$C$32,MATCH(VALUE(LEFT(C5,FIND(",",C5&",")-1)),'Feature Log'!$A$4:$A$32,0)),"") -> Terminado
A6: 2.4 | B6: Teclado y control (New Input System) | C6: 20 | D6: T16 | E6: =IFERROR(INDEX('Feature Log'!$C$4:$C$32,MATCH(VALUE(LEFT(C6,FIND(",",C6&",")-1)),'Feature Log'!$A$4:$A$32,0)),"") -> Terminado
A7: 2.4 | B7: Guardado automático en puntos de control | C7: 15 | D7: T07 | E7: =IFERROR(INDEX('Feature Log'!$C$4:$C$32,MATCH(VALUE(LEFT(C7,FIND(",",C7&",")-1)),'Feature Log'!$A$4:$A$32,0)),"") -> Terminado
A8: 2.5 | B8: Estados: Menú, Juego, Pausa, Logros, Game Over, Créditos | C8: 15 | D8: T07, T14 | E8: =IFERROR(INDEX('Feature Log'!$C$4:$C$32,MATCH(VALUE(LEFT(C8,FIND(",",C8&",")-1)),'Feature Log'!$A$4:$A$32,0)),"") -> Terminado
A9: 2.5 / 2.6 | B9: Pantalla de Opciones | C9: 16 | D9: T25 | E9: =IFERROR(INDEX('Feature Log'!$C$4:$C$32,MATCH(VALUE(LEFT(C9,FIND(",",C9&",")-1)),'Feature Log'!$A$4:$A$32,0)),"") -> Terminado
A10: 2.6 | B10: HUD: vida, maná, hechizo equipado y fragmentos | C10: 17 | D10: T14, T26 | E10: =IFERROR(INDEX('Feature Log'!$C$4:$C$32,MATCH(VALUE(LEFT(C10,FIND(",",C10&",")-1)),'Feature Log'!$A$4:$A$32,0)),"") -> Terminado
A11: 2.7 | B11: Cinco niveles (alas) con su elenco y guardián | C11: 6, 8, 10, 11 | D11: T09 a T12 | E11: =IFERROR(INDEX('Feature Log'!$C$4:$C$32,MATCH(VALUE(LEFT(C11,FIND(",",C11&",")-1)),'Feature Log'!$A$4:$A$32,0)),"") -> Terminado
A12: 2.8 | B12: Progreso: hechizos, fragmentos y coleccionables | C12: 23 | D12: T20 | E12: =IFERROR(INDEX('Feature Log'!$C$4:$C$32,MATCH(VALUE(LEFT(C12,FIND(",",C12&",")-1)),'Feature Log'!$A$4:$A$32,0)),"") -> Terminado
A13: 2.9 / 2.10 | B13: Personajes y enemigos | C13: 3, 11 | D13: T06, T22 | E13: =IFERROR(INDEX('Feature Log'!$C$4:$C$32,MATCH(VALUE(LEFT(C13,FIND(",",C13&",")-1)),'Feature Log'!$A$4:$A$32,0)),"") -> Terminado
A14: 2.11 | B14: Habilidades: Fuego quema, Hielo congela, Viento planea y empuja | C14: 5, 7, 9, 21 | D14: T23, T27 | E14: =IFERROR(INDEX('Feature Log'!$C$4:$C$32,MATCH(VALUE(LEFT(C14,FIND(",",C14&",")-1)),'Feature Log'!$A$4:$A$32,0)),"") -> Terminado
A15: 2.12 | B15: Armas de los enemigos | C15: 22 | D15: T24 | E15: =IFERROR(INDEX('Feature Log'!$C$4:$C$32,MATCH(VALUE(LEFT(C15,FIND(",",C15&",")-1)),'Feature Log'!$A$4:$A$32,0)),"") -> Terminado
... A24: 5.1 | B24: Versión web para celular (navegador y app) | C24: 28 | D24: T49, T50 | E24: =IFERROR(INDEX('Feature Log'!$C$4:$C$32,MATCH(VALUE(LEFT(C24,FIND(",",C24&",")-1)),'Feature Log'!$A$4:$A$32,0)),"") -> Terminado

Sheet Gantt
A1: DIAGRAMA DE GANTT - ECOS DEL GRIMORIO (1 sep - 30 nov, 2026)
A2: Nota: escala semanal (inicio en lunes). Verde = Terminado, ámbar = En desarrollo, gris = Planeado. Actividades de un día = hito. La semana en curso se marca en rojo.
G3: ago | H3: sep | L3: oct | P3: nov
A4: Sprint | B4: Actividad | C4: Inicio | D4: Fin | E4: Días | F4: Estado | G4: 46265 | H4: 46272 | I4: 46279 | J4: 46286 | K4: 46293 | L4: 46300 | M4: 46307 | N4: 46314 | O4: 46321 | P4: 46328 | Q4: 46335 | R4: 46342 | S4: 46349 | T4: 46356
A5: Sprint 1 | B5: Documento de diseño (GDD) | C5: 46266 | D5: 46283 | E5: =D5-C5+1 -> 18 | F5: Terminado
A6: Sprint 1 | B6: Bocetos y arte conceptual | C6: 46266 | D6: 46283 | E6: =D6-C6+1 -> 18 | F6: Terminado
A7: Sprint 1 | B7: Entrega del Producto 1 | C7: 46283 | D7: 46283 | E7: =D7-C7+1 -> 1 | F7: Terminado
A8: Sprint 2 | B8: Importar arte y código base | C8: 46284 | D8: 46295 | E8: =D8-C8+1 -> 12 | F8: Terminado
A9: Sprint 2 | B9: Herramienta CrearJuego, cinco alas y guardianes | C9: 46296 | D9: 46299 | E9: =D9-C9+1 -> 4 | F9: Terminado
A10: Sprint 2 | B10: Audio, interfaz, historia, secretos y acertijos | C10: 46300 | D10: 46300 | E10: =D10-C10+1 -> 1 | F10: Terminado
A11: Sprint 2 | B11: Correcciones, .exe, manual y documento del Producto 2 | C11: 46302 | D11: 46308 | E11: =D11-C11+1 -> 7 | F11: Terminado
A12: Sprint 2 | B12: Pruebas Alfa | C12: 46302 | D12: 46325 | E12: =D12-C12+1 -> 24 | F12: En desarrollo
A13: Sprint 2 | B13: Mejoras por las pruebas (apuntar, aves, secretos, sonidos, saltar nivel, fondos) | C13: 46310 | D13: 46316 | E13: =D13-C13+1 -> 7 | F13: Terminado
A14: Sprint 2 | B14: Versión web para celular (GitHub Pages) y ajustes en el celular | C14: 46317 | D14: 46318 | E14: =D14-C14+1 -> 2 | F14: Terminado
A15: Sprint 2 | B15: Preparar y practicar la demostración | C15: 46321 | D15: 46322 | E15: =D15-C15+1 -> 2 | F15: Planeado
A16: Sprint 2 | B16: Evaluación Beta en clase (miércoles 28 de octubre) | C16: 46323 | D16: 46323 | E16: =D16-C16+1 -> 1 | F16: Planeado
... A24: Sprint 4 | B24: Entrega final en memoria (.exe, documento y código fuente) | C24: 46356 | D24: 46356 | E24: =D24-C24+1 -> 1 | F24: Planeado

Sheet Sprint Review
A1: SPRINT REVIEW - UNA COLUMNA POR SPRINT
A2: Nota: indicadores calculados desde Sprint Backlog, Buglist y pruebas. Los campos cualitativos se completan al cierre de cada sprint.
B3: Sprint 1 | C3: Sprint 2 | D3: Sprint 3 | E3: Sprint 4
A4: Meta del sprint | B4: Preproducción: documento de diseño (GDD), bocetos y arte conceptual de personajes, enemigos, fondos, ítems y UI. | C4: Juego completo jugable en Unity con las cinco alas, jefes, logros y Modo Archimaga, listo para pruebas Alfa. | D4: Registrar los resultados de la Evaluación Beta, corregir y balancear lo que salga y tener el borrador del Postmortem. | E4: Versión final del .exe y de la web, Postmortem completo y entrega en memoria.
A5: Tareas terminadas | B5: ='Sprint Backlog'!F88&" de "&'Sprint Backlog'!E88 -> 10 de 10 | C5: ='Sprint Backlog'!F89&" de "&'Sprint Backlog'!E89 -> 48 de 53 | D5: ='Sprint Backlog'!F90&" de "&'Sprint Backlog'!E90 -> 2 de 12 | E5: ='Sprint Backlog'!F91&" de "&'Sprint Backlog'!E91 -> 0 de 7
A6: Horas terminadas | B6: ='Sprint Backlog'!H88&" de "&'Sprint Backlog'!G88&" hrs" -> 40 de 40 hrs | C6: ='Sprint Backlog'!H89&" de "&'Sprint Backlog'!G89&" hrs" -> 195 de 207 hrs | D6: ='Sprint Backlog'!H90&" de "&'Sprint Backlog'!G90&" hrs" -> 3 de 27 hrs | E6: ='Sprint Backlog'!H91&" de "&'Sprint Backlog'!G91&" hrs" -> 0 de 14 hrs
A7: Bugs corregidos | B7: =COUNTIFS(Buglist!$A$4:$A$39,1,Buglist!$F$4:$F$39,"Corregido")&" de "&COUNTIFS(Buglist!$A$4:$A$39,1,Buglist!$C$4:$C$39,"<>") -> 2 de 3 | C7: =COUNTIFS(Buglist!$A$4:$A$39,2,Buglist!$F$4:$F$39,"Corregido")&" de "&COUNTIFS(Buglist!$A$4:$A$39,2,Buglist!$C$4:$C$39,"<>") -> 17 de 18 | D7: =COUNTIFS(Buglist!$A$4:$A$39,3,Buglist!$F$4:$F$39,"Corregido")&" de "&COUNTIFS(Buglist!$A$4:$A$39,3,Buglist!$C$4:$C$39,"<>") -> 0 de 0 | E7: =COUNTIFS(Buglist!$A$4:$A$39,4,Buglist!$F$4:$F$39,"Corregido")&" de "&COUNTIFS(Buglist!$A$4:$A$39,4,Buglist!$C$4:$C$39,"<>") -> 0 de 0
A8: Pruebas | B8: Revisión del arte antes de entregarlo. | C8: ="Pruebas Alfa aprobadas: "&COUNTIF('Pruebas Alfa'!$G$4:$G$20,"Aprobada")&" de "&COUNTA('Pruebas Alfa'!$A$4:$A$20)&". Evaluación Beta en clase (28 oct): "&IF('Evaluación Beta'!G12="","pendiente",'Evaluación Beta'!G12&" puntos") -> Pruebas Alfa aprobadas: 10 de 17. Evaluación Beta en clase (28 oct): pendiente | D8: Jugar las cinco alas después de las correcciones de la Evaluación Beta. | E8: Prueba de la versión final en otra computadora y en celular.
A9: Demostración | B9: Documento de diseño y carpeta de arte entregados como Producto 1. | C9: Partida con el .exe y el control de PS4: diálogo con la Maestra Sable, combate, sala secreta, pantalla de resultados, Opciones y saltar nivel para mostrar las cinco alas y el final. También la versión web en el celular.
A10: ¿Qué salió bien? | B10: El arte de Lira, los guardianes y los fondos quedó listo a tiempo y sirvió directo para el juego. | C10: La herramienta de editor permite reconstruir todas las escenas en un clic. El código con herencia (EnemyBase, BossController) hizo rápido agregar enemigos y jefes. Se adelantaron los features de los Sprints 3 y 4.
A11: ¿Qué salió mal? | B11: Dos tareas de arte (enemigos comunes y limpieza) no se terminaron en el sprint y pasaron al Sprint 2. Algunos enemigos quedaron con un estilo distinto. | C11: Varias fallas solo aparecieron al jugar con el control (sonido, textos fuera del marco, final del juego) o en la revisión en clase (Lira flotando). El Ala de Viento quedó muy difícil por las aves. El Burn-down muestra que la mayor parte del trabajo se concentró en pocos días.
A12: Ajustes para el siguiente sprint | B12: Importar y ordenar todo el arte al inicio del Sprint 2 antes de programar. | C12: Sesiones más cortas y repartidas. Probar cada ala completa antes de agregar contenido nuevo. Practicar la demostración para la Evaluación Beta.
A13: Fecha de cierre | B13: 18 de septiembre de 2026 (Producto 1) | C13: 30 de octubre de 2026 (Producto 2) | D13: 20 de noviembre de 2026 (Producto 3) | E13: 30 de noviembre de 2026 (entrega final)
